Workbook
Name __max1: 'TRA79'!$S$9
Name _cis1: TRA61_FTA!$Y$33
Name _COM2: Index!$T$2
Name _COM3: Index!$T$3
Name _dts1: 'p2'!$AF$2
Name _FTA1: Notes!$D$3
Name _FTA3: 'TRA18'!$N$13
Name _ftn1: 'TRA90'!$R$22
Name _ftnref1: 'TRA90'!$R$6
Name _INC2: 'TRA18'!$N$15
Name _max1: 'TRA79'!$S$9
Name _nm1: 'p1'!$AJ$3
Name _ref1: 'TRA4'!$C$1
Name _reo1: Index!$C$275
Name _UA2: 'TRA18'!$N$14
Name _ver1: Notes!$S$5
Name _YA1: 'TRA30'!$M$1
Name ab: 'TRA2'!$AO$17
Name activity: Income!$E$12:$N$263
Name adet: 'TRA56'!$T$4
Name assets: 'TRA5'!$B$321:$B$339
Name assets_bpa: 'TRA6'!$B$52:$B$70
Name blanks: Index!$C$273
Name BS: 'TRA135'!$X$3:$X$242
Name bs_date_day: B_Sheet!$C$4
Name bs_date_month: B_Sheet!$D$4
Name cbmer: 'Exchange Rates'!$L$5:$S$38
Name cis: TRA61_FTA!$Z$33
Name ck: 'TRA58'!$AC$4
Name cnt: 'TRA65'!$N$5
Name COM: Index!$T$1
Name conv: 'p1'!$BK$48
Name ctry_list: 'TRA124'!$AB$1:$AB$108
Name cur: 'p1'!$Z$70
Name curr: 'p1'!$F$5
Name cv: TRA9_14!$K$155
Name dat: Index!$C$271
Name date_from: 'p1'!$G$66
Name date_month: 'TRA115'!$AA$2:$AB$13
Name date_to: 'p1'!$M$66
Name dis: 'TRA2'!$AO$19
Name dts: 'p1'!$BE$14
Name efile: Notes!$D$1
Name engagement_1: 'TRA85'!$U$4
Name ER_ya: 'p1'!$BB$48:$BE$72
Name er_ya1: 'p1'!$BB$47:$BD$71
Name eu_countries: 'TRA82'!$AL$60:$AL$86
Name EUR: Notes!$H$5
Name fi: 'TRA4'!$X$5
Name fisc: Index!$F$153
Name FO: 'TRA7'!$W$7
Name ft: 'TRA5'!$CA$3
Name FTA: Notes!$D$2
Name FU: Consolidation!$B$1:$B$51
Name fwt12a: 'TRA53'!$BC$85:$BD$86
Name FWT5A: 'TRA53'!$BC$1:$BD$12
Name ip: 'TRA5'!$CA$4
Name ipc: 'TRA35'!$AA$2
Name kambju: 'Exchange Rates'!$V$5:$W$52
Name LATE: 'TRA42'!$CP$4

Sheet Notes
D1: =IF(fisc<>0,"Electronic filing is mandatory!!","")
B2: Malta Tax & Customs Administration | D2: NOTE THAT TAXED INCOME RELIEVED BY TAX CREDITS IS ALLOCATED TO THE FINAL TAX ACCOUNT
D3: NOTE THAT INCOME SUBJECT TO FINAL WITHHOLDING TAX IS ALLOCATED TO THE FINAL TAX ACCOUNT
B5: ="NOTES ON USING THE COMPANY TAX RETURN FOR Y/A "&ya&" [VERSION CONTROL - " &_ver1 -> NOTES ON USING THE COMPANY TAX RETURN FOR Y/A 2025 [VERSION CONTROL - TA2_e-CO_2025_Ver 1.1] | D5: =F7&"_e-CO_"&ya&"_Ver 1.1" -> TA2_e-CO_2025_Ver 1.1 | F5: Version Control | H5: ="" | S5: =ver&"]" -> TA2_e-CO_2025_Ver 1.1]
B6: I M P O R T A N T to note that this spreadsheet is designed to work on MS Excel 2013 and later versions. Earlier versions of MS Office are no longer supported. | D6: (See DISCLAIMER in NOTES page)
F7: =IF(rafind=1,"TA2","AF2")
B8: GENERAL | D8: MTCA - Malta
B9: This spreadsheet version is intended solely for the electronic filing of company returns. It includes the full set of tax return attachments and the TIFD component.
B11: The exported file must be submitted through the MTCA Website http://www.cfr.gov.mt
B13: PLEASE ENSURE THAT YOU USE THE APPROPRIATE ATTACHMENTS PROVIDED TO REPORT INCOME AND TO CLAIM DEDUCTIONS, TAX CREDITS, RELIEFS, INCENTIVES, ETC. THE RETURN WILL BE CONSIDERED AS INCOMPLETE IF THE REQUIRED INFORMATION IS NOT REPORTED IN THE APPROPRIATE SPACE PROVIDED IN THE TAX RETURN AND ATTACHMENTS.
B15: DISCLAIMER
B16: This spreadsheet is intended to facilitate the filling of the company income tax return. While every effort has been made to ensure the proper functioning of this spreadsheet, the Administration does not accept any liability for erroneous results or non-compliance with legal provisions. Responsibility for the correctness of the self-assessment determination and tax calculation, in accordance with the applicable legal provisions, rests with the person signing the return. Please use the space provided on page 8 of the return to indicate and explain any 'forced' inputs or adjustments to derive a result that diverges from that derived by any automated calculation in the e-return.
B18: OPERATION AND NAVIGATION
B22: Adjust the screen size and layout to your preference.
B24: Use the TAB key to switch from one field to another. Make sure that values are allocated to the proper tax account.
B26: The workbook will not work properly with data being dragged from other cells or with the use of the cut and paste functions.
B28: VALIDATIONS AND CALCULATIONS
B30: Validations are present in all sheets.
B32: Some validations are tied to the extended questionnaire on page 2 and depend entirely on the accuracy, completeness and correctness of the answers given. For example if it is stated that the company does not benefit under the BPA all fields in the tax computation and the tax calculation referring to BPA incentives are dimmed. Any data entry in these fields will be displayed in red. The same applies for the foreign income account and the payment of dividends.
... B48: Make sure that the correct data is inputted under the proper item description. A value for each mandatory field is always required [see TIFD guidelines page 17]. However, two mandatory fields in the Balance Sheet are automatically disactivated in the case of Trusts.
XFC49: final concluded today | XFD49: 43556
B50: The two worksheets containing the TIFD component are protected. They include macros that will restrict the print area to value fields only. If multiple lines of business are present in the income statement you have to indicate the activity number to be printed in cell C 296. Once data input is complete:
B51: - click on the Print set-up button at the bottom of the sheet;
B52: - the worksheets will list only the value fields that need to be printed.
B53: You can now proceed with the print job - the print area has been pre-set. Each worksheet has another button to remove the print set-up. | IV53: 41696
B54: =ver -> TA2_e-CO_2025_Ver 1.1 | IV54: Return_2014d_67_final_3

Sheet p1
A1: =IF(AL2=1,CY2,IF(AL2=2,CZ2,DC2)) | F1: =IF(AL2=1,DA2,IF(AL2=2,DF2,DD2))
V2: =ver -> TA2_e-CO_2025_Ver 1.1 | AJ2: ="Ref: "&reg | AK2: Return / AF2 indicator / Viewing | AL2: 1 | BB2: Arab Emirates Dirham | CA2: 0 | CB2: trust indiator | CY2: TR | CZ2: FR | DA2: Income Tax Return | DC2: View | DD2: RETURN / | DF2: Further Return
F3: =IF(AL2=1,DA3,IF(AL2=2,DF3,DD3)) | AJ3: ="Name: "& NM | BB3: Australian Dollar | DA3: and Self Assessment | DD3: FURTHER RETURN | DF3: Adjustment Form
A4: =IF(AL2=1,CY4,IF(AL2=2,CZ4,"Only")) -> TA2 | V4: =IF(tr=1,"TRUST","") | AJ4: ="Name: "& NM | BB4: Canadian Dollar | CY4: TA2 | CZ4: AF2
A5: Malta Tax & Customs Administration - Malta | F5: on behalf of a Company, a Body Corporate established by Statute, a Foundation or a Trust that made an election in terms of Article 27D(1) or a Trading or Commercial Undertaking operated by an Entity (Article 30) whether resident in Malta or not | BB5: Chinese Yuan
F6: =IF(dts<>3,"NO FIELD IN THIS PART CAN BE LEFT BLANK!","") | BB6: Czech Koruna
BB7: Danish Krona
F8: Ref. No. | L8: =AG8 | Q8: =efile | AI8: =AG8 | AJ8: reposition this formula in L8 | AP8: =IF(37-MOD(MID(L8,1,1)*27+MID(L8,2,1)*32+MID(L8,3,1)*16+MID(L8,4,1)*8+MID(L8,5,1)*4+MID(L8,6,1)*2+MID(L8,7,1)*1,37)<>VALUE(RIGHT(L8,2)),0,1) | BB8: Egyptian Pound | BE8: =IF(ISBLANK(L8),0,1)
BB9: Euro Currency
F10: Name | BB10: Hong Kong Dollar | BE10: =IF(ISBLANK(L10),0,1)
BB11: Hungarian Forint
F12: Year of Assessment | L12: 2025 | BB12: Indian Rupee | BE12: =IF(ISBLANK(ya),0,1)
BB13: Japanese Yen
F14: Basis Year | L14: =IF(ISBLANK(L12),"",ya-1) | BB14: Libyan Dinar | BE14: =SUM(BE8,BE10,BE12)
BB15: New Zealand Dollar
BB16: Norwegian Krona
BB17: Peruvian Nuevo Sol
F18: MAKE SURE THAT THE CORRECT DETAILS ARE ENTERED. DATA WILL BE COPIED TO ALL OTHER PAGES IN THE RETURN. | BB18: Polish Zloty
BB19: Swedish Krona
BB20: Swiss Franc
BB21: Turkish Lira
BB22: UK Sterling
F23: 1 | G23: In pursuance of the provisions of the Income Tax Acts you are hereby required to furnish me on this form with a true and correct declaration of the income of the company, body corporate established by statute, trading or commercial undertaking or a Trust, for the basis year indicated in this return including a self-assessment computation. | BB23: US Dollars
BB24: Mexican Pesos
BB25: South African Rand
F26: 2 | G26: All income of a resident company, body corporate, trading or commercial undertaking or a Trust, accruing in or derived from Malta or elsewhere, and whether received in Malta or not, during the accounting period stated in Part 1 below, must be stated. The word "company", wherever used in this return shall where applicable be construed as a reference to a fiscal unit. | BB26: New Romanian Leu
BB27: Bulgarian lev
BB28: Israeli New Shekel
F29: 3 | G29: Except as provided in Article 68 of the Income Tax Act (Cap. 123), all income of a non-resident company, body corporate or trading or commercial undertaking, accruing in or derived from Malta, whether received in Malta or not, during the accounting period stated in Part 1 below, must be included. | BB29: Qatari Riyal
BB30: Lebanese Pound
BB31: Thai Baht
F32: 4 | G32: Full details, attachments and documentation should be given relating to all matters required to be disclosed in this return. | BB32: Brazilian Real
F33: 5 | G33: A copy of the financial statements audited by a Certified Public Accountant and Auditor MUST be attached to this return. | BB33: Nigerian Naira
F35: 6 | G35: No section of this return is to be left blank. Where there is nothing to report, the word 'NONE' should be entered.
F37: 7 | G37: The term 'Income Tax Acts' used in this return has the meaning assigned to it in Article 2 of the Income Tax Act (Cap. 123) and, unless otherwise stated, the Articles quoted in this return refer to the Income Tax Act (Cap. 123).
F39: 8 | G39: This return is to be completed and forwarded so as to reach the MTCA by not later than the last day of the ninth month following that to which the accounts for the relative financial period are made or the thirty-first March of the relative year of assessment, whichever is the later.
F42: 9 | G42: A company carrying on banking business under the Banking Act or a company carrying on the business of insurance under the Insurance Business Act or a company which is owned and controlled, directly or indirectly, by such companies shall deliver to the Commissioner a paper copy of the audited financial statements within forty-eight hours of filing an electronic tax return.
G43: Malta Tax & Customs Administration
F46: Part 1 - Company Details (Principal Taxpayer's details required in the case of a fiscal unit)
F48: 1 | G48: Partnership Number | T48: 2 | V48: VAT Number | BJ48: =VLOOKUP(cur,er_ya1,3,FALSE) | BK48: =ROUND(BJ48,1)
...

Sheet Index
B1: =_ref1 | E1: =_YA1 | G1: =E17 | K1: Prepared | T1: IS ATTACHMENT COMPLETE [Y or N] ?
R2: Yes | T2: INCOMPLETE !!
R3: No | T3: COMPLETE | CA3: ADAPT TO E-RETURN
T4: [Warning(s) present in TRA] | U4: [Warning(s) present in this page]
C6: The Malta Tax & Customs Administration uses the information provided, to process the tax return in accordance with the Income Tax Acts and subsidiary legislation. We may check information provided by you, or information about you provided by a third party or with other information held by us. We will not disclose information about the company to anyone outside the Malta Tax & Customs Administration unless permitted by law. The Malta Tax & Customs Administration treats your personal information in accordance with the Data Protection Act 2001 (Cap 440) to protect your privacy. Any queries may be addressed to The Data Controller, Malta Tax & Customs Administration, Floriana CMR 03. | G6: warn indicator | I6: name | J6: from | K6: to
C7: =IF(E7=0,0,IF(E7=1,1,IF(E7=100,"x"))) | D7: Balance Sheet | E7: =B_Sheet!G272 | G7: =B_Sheet!I3 | I7: B_Sheet | J7: 6 | K7: 261 | AJ7: value!
C8: =IF(E8=0,0,IF(E8=1,1,IF(E8=100,"x"))) -> 1 | D8: Income Statement | E8: =Income!P298 | I8: Income | J8: 6 | K8: 288 | AJ8: loss ??
B9: TRA 01 | C9: =IF(E9=0,0,IF(E9=1,1,IF(E9=100,"x"))) -> 0 | D9: ITA - Article 14(1)(h) - Scientific Research | E9: ='TRA1'!I60 | F9: =E9 | I9: TRA1 | J9: 231 | K9: 274
B10: TRA 02 | C10: =IF(E10=0,0,IF(E10=1,1,IF(E10=100,"x"))) -> 0 | D10: BPA - Regulation 13 - Incentive for job creation | E10: ='TRA2'!K55 | F10: =E10 | H10: TRA2 | I10: TRA2 | J10: 278 | K10: 300
B11: TRA 03 | C11: =IF(E11=0,0,IF(E11=1,1,IF(E11=100,"x"))) -> 0 | D11: Other statutory inflation of expenditure | E11: ='TRA3'!J35 | F11: =E11 | I11: TRA3 | J11: 304 | K11: 330
B12: TRA 04 | C12: =IF(E12=0,0,IF(E12=1,1,IF(E12=100,"x"))) -> 0 | D12: =IF(G12=1,BA12&warn,BA12) | E12: ='TRA4'!N106 | G12: ='TRA4'!R108 | I12: TRA4 | J12: 334 | K12: 368 | BA12: ITA - Balancing statement
B13: TRA 05 | C13: =IF(E13=0,0,IF(E13=1,1,IF(E13=100,"x"))) -> 1 | D13: =IF(G13=1,BA13&warn,BA13) -> ITA - Capital allowances | E13: ='TRA5'!S307 | G13: ='TRA5'!S309 | H13: TRA5 | I13: TRA5 | J13: 372 | K13: 491 | BA13: ITA - Capital allowances
B14: TRA 06 | C14: =IF(E14=0,0,IF(E14=1,1,IF(E14=100,"x"))) -> 0 | D14: =IF(G14=1,BA14&warn,BA14) -> BPA [Article 7] - Investment Allowance | E14: ='TRA6'!L48 | F14: =E14 | I14: TRA6 | J14: 495 | K14: 523 | BA14: BPA [Article 7] - Investment Allowance
B15: TRA 07 | C15: =IF(E15=0,0,IF(E15=1,1,IF(E15=100,"x"))) -> 0 | D15: =IF(G15=1,BA15&warn,BA15) -> BPA [Article 8] - Accelerated Depreciation | E15: ='TRA7'!P23 | F15: =E15 | G15: ='TRA7'!P25 | H15: TRA7 | I15: TRA7 | J15: 527 | K15: 534 | BA15: BPA [Article 8] - Accelerated Depreciation
B16: TRA 08 | C16: =IF(E16=0,0,IF(E16=1,1,IF(E16=100,"x"))) -> 0 | D16: =IF(G16=1,BA16&warn,BA16) -> ITA - Dividend(s) | E16: ='TRA8'!N105 | F16: ='TRA8'!C90 | G16: ='TRA8'!R3 | H16: TRA8 | I16: TRA8 | J16: 538 | K16: 570 | BA16: ITA - Dividend(s)
B17: TRA 09 | C17: =IF(E17=0,0,IF(E17=1,1,IF(E17=100,"x"))) -> 0 | D17: ITA - Interests | E17: =TRA9_14!I27 | F17: 10000 | I17: TRA9_14 | J17: =IF(AND(L17=0,SUM(M19:O19)>0),re,IF(L17=0,"",IF(L17<4,"All Details!",IF(N17>1,"Multiple Tax Accounts!","")))) | K17: 586 | BA17: ITA - Interest(s)
B18: TRA 10 | C18: =IF(E18=0,0,IF(E18=1,1,IF(E18=100,"x"))) -> 0 | D18: =IF(G18=1,BA18&warn,BA18) -> ITA - Discounts or premiums | E18: =TRA9_14!I57 | G18: =TRA9_14!J57 | H18: TRA10 | I18: TRA9_14 | J18: 587 | K18: 597 | BA18: ITA - Discounts or premiums
B19: TRA 11 | C19: =IF(E19=0,0,IF(E19=1,1,IF(E19=100,"x"))) -> 0 | D19: =IF(G19=1,BA19&warn,BA19) -> ITA - Income from Rent(s) | E19: =TRA9_14!I79 | G19: =TRA9_14!I80 | I19: TRA9_14 | J19: 598 | K19: 609 | BA19: ITA - Income from Rent(s)
B20: TRA 12 | C20: =IF(E20=0,0,IF(E20=1,1,IF(E20=100,"x"))) -> 0 | D20: =IF(G20=1,BA20&warn,BA20) -> ITA - Income from Ground Rent(s) | E20: =TRA9_14!I103 | G20: =TRA9_14!I104 | I20: TRA9_14 | J20: 610 | K20: 618 | BA20: ITA - Income from Ground Rent(s)
B21: TRA 13 | C21: =IF(E21=0,0,IF(E21=1,1,IF(E21=100,"x"))) -> 0 | D21: =IF(G21=1,BA21&warn,BA21) -> ITA - Income from Royalties, etc. | E21: =TRA9_14!I127 | G21: =TRA9_14!I128 | H21: TRA13 | I21: TRA9_14 | J21: 619 | K21: 628 | BA21: ITA - Income from Royalties, etc.
B22: TRA 14 | C22: =IF(E22=0,0,IF(E22=1,1,IF(E22=100,"x"))) -> 0 | D22: =IF(G22=1,BA22&warn,BA22) -> ITA - Other income | E22: =TRA9_14!I153 | G22: =TRA9_14!I154 | I22: TRA9_14 | J22: 629 | K22: 641 | BA22: ITA - Other income
B23: TRA 15 | C23: =IF(E23=0,0,IF(E23=1,1,IF(E23=100,"x"))) -> 0 | D23: ITA - Capital gain/(loss) - Summary | E23: ='TRA15'!K92 | I23: TRA15 | J23: 644 | K23: 651
B24: TRA 16 | C24: =IF(E24=0,0,IF(E24=1,1,IF(E24=100,"x"))) -> 0 | D24: ITA - Capital gain/(loss) - Immovable Property | E24: ='TRA16'!K1036 | I24: TRA16 | J24: 656 | K24: 748
B25: TRA 17 | C25: =IF(E25=0,0,IF(E25=1,1,IF(E25=100,"x"))) -> 0 | D25: ITA - Capital gain/(loss) - Securities | E25: ='TRA17'!Q680 | H25: TRA17 | I25: TRA17 | J25: 751 | K25: 777
B26: TRA 18 | C26: =IF(E26=0,0,IF(E26=1,1,IF(E26=100,"x"))) -> 0 | D26: =IF(G26=1,BA26&warn,BA26) | E26: ='TRA18'!L64 | F26: =E26 | G26: ='TRA18'!L73 | H26: TRA18 | I26: TRA18 | J26: 779 | K26: 805 | BA26: Total Exempt Income
B27: TRA 19 | C27: =IF(E27=0,0,IF(E27=1,1,IF(E27=100,"x"))) -> 0 | D27: =IF(G27=1,BA27&warn,BA27) | E27: ='TRA19'!R40 | G27: ='TRA19'!P36 | H27: TRA19 | I27: TRA19 | J27: 808 | K27: 827 | BA27: ITA - Loss SURRENDERED to group company/companies
B28: TRA 20 | C28: =IF(E28=0,0,IF(E28=1,1,IF(E28=100,"x"))) -> 0 | D28: =IF(G28=1,BA28&warn,BA28) | E28: ='TRA20'!R52 | G28: 0 | H28: TRA20 | I28: TRA20 | J28: 831 | K28: 853 | BA28: ITA - Group loss CLAIMED - current year
B29: TRA 21 | C29: =IF(E29=0,0,IF(E29=1,1,IF(E29=100,"x"))) -> 0 | D29: BPA - Article 5 | E29: 0
B30: TRA 22 | C30: =IF(E30=0,0,IF(E30=1,1,IF(E30=100,"x"))) -> 0 | D30: BPA - Article 5A | E30: 0
B31: TRA 23 | C31: =IF(E31=0,0,IF(E31=1,1,IF(E31=100,"x"))) -> 0 | D31: BPA - Article 6 | E31: =TRA23_24!N42 | F31: =E31 | H31: TRA23 | I31: TRA23_24 | J31: 857 | K31: 874
B32: TRA 24 | C32: =IF(E32=0,0,IF(E32=1,1,IF(E32=100,"x"))) -> 0 | D32: BPA - Article 24B | E32: =TRA23_24!O42 | F32: =E32 -> 0 | G32: 100 | H32: TRA24 | I32: TRA23_24 | J32: 857 | K32: 874
B33: TRA 25 | C33: =IF(E33=0,0,IF(E33=1,1,IF(E33=100,"x"))) -> 0 | D33: BPA - Regulation 4 (Reduced Rates of Income Tax) | BA33: BPA - Regulation 4 (Reduced Rates of Income Tax)
B34: TRA 26 | C34: =IF(E34=0,0,IF(E34=1,1,IF(E34=100,"x"))) -> 0 | D34: BPA - Regulation 6 (Value Added Incentive Scheme)
B35: TRA 27 | C35: =IF(E35=0,0,IF(E35=1,1,IF(E35=100,"x"))) -> 0 | D35: ITA - Article 56(20) (Double Taxation Treaties) | E35: =TRA27_28!M49 | F35: =E35 -> 0 | H35: TRA27 | I35: TRA27_28 | J35: 877 | K35: 909
B36: TRA 28 | C36: =IF(E36=0,0,IF(E36=1,1,IF(E36=100,"x"))) -> 0 | D36: BPA Article 15 (Double Taxation Treaties) | E36: =TRA27_28!M50 | F36: =E36 -> 0 | H36: TRA28 | I36: TRA27_28 | J36: 877 | K36: 909
B37: TRA 29 | C37: =IF(E37=0,0,IF(E37=1,1,IF(E37=100,"x"))) -> 0 | D37: =IF(G37=1,BA37&warn,BA37) | E37: ='TRA29'!J115 | F37: =E37 -> 0 | G37: 2000 | H37: TRA29 | I37: TRA29 | J37: 913 | K37: 920 | BA37: BPA - Regulation 5 (Investment Tax Credit)
B38: TRA 30 | C38: =IF(E38=0,0,IF(E38=1,1,IF(E38=100,"x"))) -> 0 | D38: =IF(G38=1,BA38&warn,BA38) | E38: ='TRA30'!P29 | G38: =IF('TRA30'!H25="",0,1) | H38: TRA30 | I38: TRA30 | J38: 925 | K38: 936 | BA38: Relief of double taxation
B39: TRA 31 | C39: =IF(E39=0,0,IF(E39=1,1,IF(E39=100,"x"))) -> 1 | D39: Tax paid | E39: ='TRA31'!K168 | H39: TRA31 | I39: TRA31 | J39: 940 | K39: 992
B40: TRA 32 | C40: =IF(E40=0,0,IF(E40=1,1,IF(E40=100,"x"))) -> 0 | D40: Investment Income subject to 15% Final Withholding Tax | E40: 0
B41: TRA 33 | C41: =IF(E41=0,0,IF(E41=1,1,IF(E41=100,"x"))) -> 0 | D41: Income subject to reduced rates of tax - Summary | E41: ='TRA33'!L32 | F41: =E41 | H41: TRA33 | I41: TRA33 | J41: 996 | K41: 1012
...

Sheet B_Sheet
A1: a | B1: Back to Index | BA1: =IF('p1'!M66="",DATE(ya-1,12,31),'p1'!M66)
A2: 1 | B2: =_ref1 | E2: =_YA1 | AY2: =IF(AZ2<>BA2,1,0) | AZ2: =C4 | BA2: =DAY(BA1)
A3: 0 | C3: =IF(AND(C4="",D4=""),"",IF(AY4<>0,"Accounting year end does not match MTCA records! Please Rectify.","")) | I3: =IF(C3="",0,1) | AY3: =IF(AZ3<>BA3,1,0) | AZ3: =VLOOKUP(D4,AM6:AN17,2,FALSE) | BA3: =MONTH(BA1)
A4: 1 | B4: Balance Sheet as at | C4: 31 | D4: December | E4: =ya-1 | F4: =IF(ISBLANK(C4),H4,IF(ISBLANK(D4),H4,"")) | G4: =IF(F4="",0,1) | H4: Full date! | AY4: =SUM(AY2:AY3)
A5: 0 | B5: Item Description | C5: Code | E5: Dr ( + ) or Cr ( - )
A6: =COUNT(E6) | B6: Intangible assets | C6: 1000 | F6: =IF(E6<0,"Negative amount!","") | H6: =IF(F6="",0,1) | Z6: =IF(A6=1,SUM($A$6:$A6),0) | AL6: 1 | AM6: January | AN6: 1
A7: =COUNT(E7) | B7: Accumulated amortisation of intangible assets | C7: 1001 | F7: =IF(E7>0,"Positive amount!","") | H7: =IF(F7="",0,1) -> 0 | Z7: =IF(A7=1,SUM($A$6:$A7),0) | AL7: 2 | AM7: February | AN7: 2
A8: =COUNT(E8) -> 0 | B8: Goodwill | C8: 1002 | F8: =IF(E8<0,"Negative amount!","") | H8: =IF(F8="",0,1) -> 0 | Z8: =IF(A8=1,SUM($A$6:$A8),0) | AL8: 3 | AM8: March | AN8: 3
A9: =COUNT(E9) -> 0 | B9: Accumulated amortisation of goodwill | C9: 1003 | F9: =IF(E9>0,"Positive amount!","") | H9: =IF(F9="",0,1) -> 0 | Z9: =IF(A9=1,SUM($A$6:$A9),0) | AL9: 4 | AM9: April | AN9: 4
A10: =COUNT(E10) -> 0 | B10: Formation expenses | C10: 1004 | F10: =IF(E10<0,"Negative amount!","") | H10: =IF(F10="",0,1) -> 0 | Z10: =IF(A10=1,SUM($A$6:$A10),0) | AL10: 5 | AM10: May | AN10: 5
A11: =COUNT(E11) -> 0 | B11: Accumulated amortisation of formation expenses | C11: 1005 | F11: =IF(E11>0,"Positive amount!","") | H11: =IF(F11="",0,1) -> 0 | Z11: =IF(A11=1,SUM($A$6:$A11),0) | AL11: 6 | AM11: June | AN11: 6
A12: =COUNT(E12) -> 1 | B12: Royalties, trademarks, patents, rights, etc. | C12: 1006 | F12: =IF(E12<0,"Negative amount!","") | H12: =IF(F12="",0,1) -> 0 | Z12: =IF(A12=1,SUM($A$6:$A12),0) | AL12: 7 | AM12: July | AN12: 7
A13: =COUNT(E13) -> 1 | B13: Accumulated amortisation of royalties, trademarks, patents | C13: 1007 | F13: =IF(E13>0,"Positive amount!","") | H13: =IF(F13="",0,1) -> 0 | Z13: =IF(A13=1,SUM($A$6:$A13),0) | AL13: 8 | AM13: August | AN13: 8
A14: =COUNT(E14) -> 0 | B14: Research and development (capitalised) | C14: 1008 | F14: =IF(E14<0,"Negative amount!","") | H14: =IF(F14="",0,1) -> 0 | Z14: =IF(A14=1,SUM($A$6:$A14),0) | AL14: 9 | AM14: September | AN14: 9
A15: =COUNT(E15) -> 0 | B15: Accumulated amortisation of research and development | C15: 1009 | F15: =IF(E15>0,"Positive amount!","") | H15: =IF(F15="",0,1) -> 0 | Z15: =IF(A15=1,SUM($A$6:$A15),0) | AL15: 10 | AM15: October | AN15: 10
A16: 1 | B16: Total Intangible assets | C16: 1198 | E16: =SUM(E6,E8,E10,E12,E14) | Y16: 1 | Z16: =IF(A16=1,SUM($A$6:$A16),0) | AL16: 11 | AM16: November | AN16: 11 | CA16: 1
A17: 1 | B17: Total accumulated amortisation of intangible assets | C17: 1199 | E17: =SUM(E7,E9,E11,E13,E15) | Y17: 1 | Z17: =IF(A17=1,SUM($A$6:$A17),0) | AL17: 12 | AM17: December | AN17: 12 | CA17: 1
A18: =COUNT(E18) -> 0 | B18: Land and Buildings | C18: 1200 | F18: =IF(E18<0,"Negative amount!","") | H18: =IF(F18="",0,1) | Z18: =IF(A18=1,SUM($A$6:$A18),0) | AL18: 13
A19: =COUNT(E19) -> 0 | B19: Accumulated depreciation of land and buildings | C19: 1201 | F19: =IF(E19>0,"Positive amount!","") | H19: =IF(F19="",0,1) -> 0 | Z19: =IF(A19=1,SUM($A$6:$A19),0) | AL19: 14
A20: =COUNT(E20) -> 0 | B20: Land improvements | C20: 1202 | F20: =IF(E20<0,"Negative amount!","") | H20: =IF(F20="",0,1) -> 0 | Z20: =IF(A20=1,SUM($A$6:$A20),0) | AL20: 15
A21: =COUNT(E21) -> 0 | B21: Accumulated depreciation of land improvements | C21: 1203 | F21: =IF(E21>0,"Positive amount!","") | H21: =IF(F21="",0,1) -> 0 | Z21: =IF(A21=1,SUM($A$6:$A21),0) | AL21: 16
A22: =COUNT(E22) -> 0 | B22: Industrial Buildings and structures | C22: 1204 | F22: =IF(E22<0,"Negative amount!","") | H22: =IF(F22="",0,1) -> 0 | Z22: =IF(A22=1,SUM($A$6:$A22),0) | AL22: 17
A23: =COUNT(E23) -> 0 | B23: Accumulated depreciation of industrial buildings and structures | C23: 1205 | F23: =IF(E23>0,"Positive amount!","") | H23: =IF(F23="",0,1) -> 0 | Z23: =IF(A23=1,SUM($A$6:$A23),0) | AL23: 18
A24: =COUNT(E24) -> 0 | B24: Non-industrial buildings | C24: 1206 | F24: =IF(E24<0,"Negative amount!","") | H24: =IF(F24="",0,1) -> 0 | Z24: =IF(A24=1,SUM($A$6:$A24),0) | AL24: 19
A25: =COUNT(E25) -> 0 | B25: Accumulated depreciation of non-industrial buildings | C25: 1207 | F25: =IF(E25>0,"Positive amount!","") | H25: =IF(F25="",0,1) -> 0 | Z25: =IF(A25=1,SUM($A$6:$A25),0) | AL25: 20
A26: =COUNT(E26) -> 0 | B26: Parking areas | C26: 1208 | F26: =IF(E26<0,"Negative amount!","") | H26: =IF(F26="",0,1) -> 0 | Z26: =IF(A26=1,SUM($A$6:$A26),0) | AL26: 21
A27: =COUNT(E27) -> 0 | B27: Accumulated depreciation of parking areas | C27: 1209 | F27: =IF(E27>0,"Positive amount!","") | H27: =IF(F27="",0,1) -> 0 | Z27: =IF(A27=1,SUM($A$6:$A27),0) | AL27: 22
A28: =COUNT(E28) -> 0 | B28: Buildings under construction | C28: 1210 | F28: =IF(E28<0,"Negative amount!","") | H28: =IF(F28="",0,1) -> 0 | Z28: =IF(A28=1,SUM($A$6:$A28),0) | AL28: 23
A29: =COUNT(E29) -> 0 | B29: Wasting assets | C29: 1300 | F29: =IF(E29<0,"Negative amount!","") | H29: =IF(F29="",0,1) -> 0 | Z29: =IF(A29=1,SUM($A$6:$A29),0) | AL29: 24
A30: =COUNT(E30) -> 0 | B30: Accumulated depreciation of wasting assets | C30: 1301 | F30: =IF(E30>0,"Positive amount!","") | H30: =IF(F30="",0,1) -> 0 | Z30: =IF(A30=1,SUM($A$6:$A30),0) | AL30: 25
A31: =COUNT(E31) -> 0 | B31: Petroleum and natural gas properties | C31: 1302 | F31: =IF(E31<0,"Negative amount!","") | H31: =IF(F31="",0,1) -> 0 | Z31: =IF(A31=1,SUM($A$6:$A31),0) | AL31: 26
A32: =COUNT(E32) -> 0 | B32: Accumulated depreciation of petroleum and natural gas properties | C32: 1303 | F32: =IF(E32>0,"Positive amount!","") | H32: =IF(F32="",0,1) -> 0 | Z32: =IF(A32=1,SUM($A$6:$A32),0) | AL32: 27
A33: =COUNT(E33) -> 0 | B33: Deferred exploration and development charges | C33: 1304 | F33: =IF(E33<0,"Negative amount!","") | H33: =IF(F33="",0,1) -> 0 | Z33: =IF(A33=1,SUM($A$6:$A33),0) | AL33: 28
A34: =COUNT(E34) -> 0 | B34: Accumulated depreciation of deferred exploration and development charges | C34: 1305 | F34: =IF(E34>0,"Positive amount!","") | H34: =IF(F34="",0,1) -> 0 | Z34: =IF(A34=1,SUM($A$6:$A34),0) | AL34: 29
A35: =COUNT(E35) -> 0 | B35: Quarries | C35: 1306 | F35: =IF(E35<0,"Negative amount!","") | H35: =IF(F35="",0,1) -> 0 | Z35: =IF(A35=1,SUM($A$6:$A35),0) | AL35: 30
A36: =COUNT(E36) -> 0 | B36: Accumulated depreciation of quarries | C36: 1307 | F36: =IF(E36>0,"Positive amount!","") | H36: =IF(F36="",0,1) -> 0 | Z36: =IF(A36=1,SUM($A$6:$A36),0) | AL36: 31
A37: =COUNT(E37) -> 0 | B37: Plant and machinery | C37: 1350 | F37: =IF(E37<0,"Negative amount!","") | H37: =IF(F37="",0,1) -> 0 | Z37: =IF(A37=1,SUM($A$6:$A37),0)
A38: =COUNT(E38) -> 0 | B38: Accumulated depreciation of plant and machinery | C38: 1351 | F38: =IF(E38>0,"Positive amount!","") | H38: =IF(F38="",0,1) -> 0 | Z38: =IF(A38=1,SUM($A$6:$A38),0)
A39: =COUNT(E39) -> 0 | B39: Motor vehicles | C39: 1352 | F39: =IF(E39<0,"Negative amount!","") | H39: =IF(F39="",0,1) -> 0 | Z39: =IF(A39=1,SUM($A$6:$A39),0)
A40: =COUNT(E40) -> 0 | B40: Accumulated depreciation of motor vehicles | C40: 1353 | F40: =IF(E40>0,"Positive amount!","") | H40: =IF(F40="",0,1) -> 0 | Z40: =IF(A40=1,SUM($A$6:$A40),0)
...

Sheet B_Sheet_Summary
B4: =B_Sheet!B4 -> Balance Sheet as at | C4: =B_Sheet!C4&" "&B_Sheet!D4&" "&B_Sheet!E4
B5: Item Description | C5: Code | D5: Value
B6: =IF(ROW() -5<= MAX(B_Sheet!$Z$6:$Z$263),INDEX(B_Sheet!$B$6:$Z$263,MATCH(ROW()-5,B_Sheet!$Z$6:$Z$263,0),1),"") | C6: =IF(ROW() -5<= MAX(B_Sheet!$Z$6:$Z$263),INDEX(B_Sheet!$B$6:$Z$263,MATCH(ROW()-5,B_Sheet!$Z$6:$Z$263,0),2),"") | D6: =IF(ROW() -5<= MAX(B_Sheet!$Z$6:$Z$263),INDEX(B_Sheet!$B$6:$Z$263,MATCH(ROW()-5,B_Sheet!$Z$6:$Z$263,0),4),"") | G6: =IF(ROW()-5<=MAX(B_Sheet!$Z$6:$Z$263),INDEX(B_Sheet!$B$6:$Z$263,MATCH(ROW()-5,B_Sheet!$Z$6:$Z$263,0),24),"")
B7: =IF(ROW() -5<= MAX(B_Sheet!$Z$6:$Z$263),INDEX(B_Sheet!$B$6:$Z$263,MATCH(ROW()-5,B_Sheet!$Z$6:$Z$263,0),1),"") | C7: =IF(ROW() -5<= MAX(B_Sheet!$Z$6:$Z$263),INDEX(B_Sheet!$B$6:$Z$263,MATCH(ROW()-5,B_Sheet!$Z$6:$Z$263,0),2),"") | D7: =IF(ROW() -5<= MAX(B_Sheet!$Z$6:$Z$263),INDEX(B_Sheet!$B$6:$Z$263,MATCH(ROW()-5,B_Sheet!$Z$6:$Z$263,0),4),"") | G7: =IF(ROW()-5<=MAX(B_Sheet!$Z$6:$Z$263),INDEX(B_Sheet!$B$6:$Z$263,MATCH(ROW()-5,B_Sheet!$Z$6:$Z$263,0),24),"")
B8: =IF(ROW() -5<= MAX(B_Sheet!$Z$6:$Z$263),INDEX(B_Sheet!$B$6:$Z$263,MATCH(ROW()-5,B_Sheet!$Z$6:$Z$263,0),1),"") | C8: =IF(ROW() -5<= MAX(B_Sheet!$Z$6:$Z$263),INDEX(B_Sheet!$B$6:$Z$263,MATCH(ROW()-5,B_Sheet!$Z$6:$Z$263,0),2),"") | D8: =IF(ROW() -5<= MAX(B_Sheet!$Z$6:$Z$263),INDEX(B_Sheet!$B$6:$Z$263,MATCH(ROW()-5,B_Sheet!$Z$6:$Z$263,0),4),"") | G8: =IF(ROW()-5<=MAX(B_Sheet!$Z$6:$Z$263),INDEX(B_Sheet!$B$6:$Z$263,MATCH(ROW()-5,B_Sheet!$Z$6:$Z$263,0),24),"")
B9: =IF(ROW() -5<= MAX(B_Sheet!$Z$6:$Z$263),INDEX(B_Sheet!$B$6:$Z$263,MATCH(ROW()-5,B_Sheet!$Z$6:$Z$263,0),1),"") | C9: =IF(ROW() -5<= MAX(B_Sheet!$Z$6:$Z$263),INDEX(B_Sheet!$B$6:$Z$263,MATCH(ROW()-5,B_Sheet!$Z$6:$Z$263,0),2),"") | D9: =IF(ROW() -5<= MAX(B_Sheet!$Z$6:$Z$263),INDEX(B_Sheet!$B$6:$Z$263,MATCH(ROW()-5,B_Sheet!$Z$6:$Z$263,0),4),"") | G9: =IF(ROW()-5<=MAX(B_Sheet!$Z$6:$Z$263),INDEX(B_Sheet!$B$6:$Z$263,MATCH(ROW()-5,B_Sheet!$Z$6:$Z$263,0),24),"")
B10: =IF(ROW() -5<= MAX(B_Sheet!$Z$6:$Z$263),INDEX(B_Sheet!$B$6:$Z$263,MATCH(ROW()-5,B_Sheet!$Z$6:$Z$263,0),1),"") | C10: =IF(ROW() -5<= MAX(B_Sheet!$Z$6:$Z$263),INDEX(B_Sheet!$B$6:$Z$263,MATCH(ROW()-5,B_Sheet!$Z$6:$Z$263,0),2),"") | D10: =IF(ROW() -5<= MAX(B_Sheet!$Z$6:$Z$263),INDEX(B_Sheet!$B$6:$Z$263,MATCH(ROW()-5,B_Sheet!$Z$6:$Z$263,0),4),"") | G10: =IF(ROW()-5<=MAX(B_Sheet!$Z$6:$Z$263),INDEX(B_Sheet!$B$6:$Z$263,MATCH(ROW()-5,B_Sheet!$Z$6:$Z$263,0),24),"")
B11: =IF(ROW() -5<= MAX(B_Sheet!$Z$6:$Z$263),INDEX(B_Sheet!$B$6:$Z$263,MATCH(ROW()-5,B_Sheet!$Z$6:$Z$263,0),1),"") | C11: =IF(ROW() -5<= MAX(B_Sheet!$Z$6:$Z$263),INDEX(B_Sheet!$B$6:$Z$263,MATCH(ROW()-5,B_Sheet!$Z$6:$Z$263,0),2),"") | D11: =IF(ROW() -5<= MAX(B_Sheet!$Z$6:$Z$263),INDEX(B_Sheet!$B$6:$Z$263,MATCH(ROW()-5,B_Sheet!$Z$6:$Z$263,0),4),"") | G11: =IF(ROW()-5<=MAX(B_Sheet!$Z$6:$Z$263),INDEX(B_Sheet!$B$6:$Z$263,MATCH(ROW()-5,B_Sheet!$Z$6:$Z$263,0),24),"")
B12: =IF(ROW() -5<= MAX(B_Sheet!$Z$6:$Z$263),INDEX(B_Sheet!$B$6:$Z$263,MATCH(ROW()-5,B_Sheet!$Z$6:$Z$263,0),1),"") | C12: =IF(ROW() -5<= MAX(B_Sheet!$Z$6:$Z$263),INDEX(B_Sheet!$B$6:$Z$263,MATCH(ROW()-5,B_Sheet!$Z$6:$Z$263,0),2),"") | D12: =IF(ROW() -5<= MAX(B_Sheet!$Z$6:$Z$263),INDEX(B_Sheet!$B$6:$Z$263,MATCH(ROW()-5,B_Sheet!$Z$6:$Z$263,0),4),"") | G12: =IF(ROW()-5<=MAX(B_Sheet!$Z$6:$Z$263),INDEX(B_Sheet!$B$6:$Z$263,MATCH(ROW()-5,B_Sheet!$Z$6:$Z$263,0),24),"")
B13: =IF(ROW() -5<= MAX(B_Sheet!$Z$6:$Z$263),INDEX(B_Sheet!$B$6:$Z$263,MATCH(ROW()-5,B_Sheet!$Z$6:$Z$263,0),1),"") | C13: =IF(ROW() -5<= MAX(B_Sheet!$Z$6:$Z$263),INDEX(B_Sheet!$B$6:$Z$263,MATCH(ROW()-5,B_Sheet!$Z$6:$Z$263,0),2),"") | D13: =IF(ROW() -5<= MAX(B_Sheet!$Z$6:$Z$263),INDEX(B_Sheet!$B$6:$Z$263,MATCH(ROW()-5,B_Sheet!$Z$6:$Z$263,0),4),"") | G13: =IF(ROW()-5<=MAX(B_Sheet!$Z$6:$Z$263),INDEX(B_Sheet!$B$6:$Z$263,MATCH(ROW()-5,B_Sheet!$Z$6:$Z$263,0),24),"")
B14: =IF(ROW() -5<= MAX(B_Sheet!$Z$6:$Z$263),INDEX(B_Sheet!$B$6:$Z$263,MATCH(ROW()-5,B_Sheet!$Z$6:$Z$263,0),1),"") | C14: =IF(ROW() -5<= MAX(B_Sheet!$Z$6:$Z$263),INDEX(B_Sheet!$B$6:$Z$263,MATCH(ROW()-5,B_Sheet!$Z$6:$Z$263,0),2),"") | D14: =IF(ROW() -5<= MAX(B_Sheet!$Z$6:$Z$263),INDEX(B_Sheet!$B$6:$Z$263,MATCH(ROW()-5,B_Sheet!$Z$6:$Z$263,0),4),"") | G14: =IF(ROW()-5<=MAX(B_Sheet!$Z$6:$Z$263),INDEX(B_Sheet!$B$6:$Z$263,MATCH(ROW()-5,B_Sheet!$Z$6:$Z$263,0),24),"")
B15: =IF(ROW() -5<= MAX(B_Sheet!$Z$6:$Z$263),INDEX(B_Sheet!$B$6:$Z$263,MATCH(ROW()-5,B_Sheet!$Z$6:$Z$263,0),1),"") | C15: =IF(ROW() -5<= MAX(B_Sheet!$Z$6:$Z$263),INDEX(B_Sheet!$B$6:$Z$263,MATCH(ROW()-5,B_Sheet!$Z$6:$Z$263,0),2),"") | D15: =IF(ROW() -5<= MAX(B_Sheet!$Z$6:$Z$263),INDEX(B_Sheet!$B$6:$Z$263,MATCH(ROW()-5,B_Sheet!$Z$6:$Z$263,0),4),"") | G15: =IF(ROW()-5<=MAX(B_Sheet!$Z$6:$Z$263),INDEX(B_Sheet!$B$6:$Z$263,MATCH(ROW()-5,B_Sheet!$Z$6:$Z$263,0),24),"")
B16: =IF(ROW() -5<= MAX(B_Sheet!$Z$6:$Z$263),INDEX(B_Sheet!$B$6:$Z$263,MATCH(ROW()-5,B_Sheet!$Z$6:$Z$263,0),1),"") | C16: =IF(ROW() -5<= MAX(B_Sheet!$Z$6:$Z$263),INDEX(B_Sheet!$B$6:$Z$263,MATCH(ROW()-5,B_Sheet!$Z$6:$Z$263,0),2),"") | D16: =IF(ROW() -5<= MAX(B_Sheet!$Z$6:$Z$263),INDEX(B_Sheet!$B$6:$Z$263,MATCH(ROW()-5,B_Sheet!$Z$6:$Z$263,0),4),"") | G16: =IF(ROW()-5<=MAX(B_Sheet!$Z$6:$Z$263),INDEX(B_Sheet!$B$6:$Z$263,MATCH(ROW()-5,B_Sheet!$Z$6:$Z$263,0),24),"")
B17: =IF(ROW() -5<= MAX(B_Sheet!$Z$6:$Z$263),INDEX(B_Sheet!$B$6:$Z$263,MATCH(ROW()-5,B_Sheet!$Z$6:$Z$263,0),1),"") | C17: =IF(ROW() -5<= MAX(B_Sheet!$Z$6:$Z$263),INDEX(B_Sheet!$B$6:$Z$263,MATCH(ROW()-5,B_Sheet!$Z$6:$Z$263,0),2),"") | D17: =IF(ROW() -5<= MAX(B_Sheet!$Z$6:$Z$263),INDEX(B_Sheet!$B$6:$Z$263,MATCH(ROW()-5,B_Sheet!$Z$6:$Z$263,0),4),"") | G17: =IF(ROW()-5<=MAX(B_Sheet!$Z$6:$Z$263),INDEX(B_Sheet!$B$6:$Z$263,MATCH(ROW()-5,B_Sheet!$Z$6:$Z$263,0),24),"")
... B261: =IF(ROW() -5<= MAX(B_Sheet!$Z$6:$Z$263),INDEX(B_Sheet!$B$6:$Z$263,MATCH(ROW()-5,B_Sheet!$Z$6:$Z$263,0),1),"") | C261: =IF(ROW() -5<= MAX(B_Sheet!$Z$6:$Z$263),INDEX(B_Sheet!$B$6:$Z$263,MATCH(ROW()-5,B_Sheet!$Z$6:$Z$263,0),2),"") | D261: =IF(ROW() -5<= MAX(B_Sheet!$Z$6:$Z$263),INDEX(B_Sheet!$B$6:$Z$263,MATCH(ROW()-5,B_Sheet!$Z$6:$Z$263,0),4),"") | G261: =IF(ROW()-5<=MAX(B_Sheet!$Z$6:$Z$263),INDEX(B_Sheet!$B$6:$Z$263,MATCH(ROW()-5,B_Sheet!$Z$6:$Z$263,0),24),"")

Sheet IRDAddin
A1: Name | B1: CompanyTaxReturn09
A2: Version | B2: 9.2
A3: GUID | B3: 89182126-b648-485f-b910-560b60b5c4da
A4: TP | B4: =reg
A5: Year | B5: =ya
A6: Complete | B6: =IF(Index!E155<>0,1,IF(Index!G155<>0,2,0))

Sheet Consolidation
A1: FU_PRINC | D1: =COUNTA(FU)
A2: FU_MEM_1
A3: FU_MEM_2
A4: FU_MEM_3
A5: FU_MEM_4
A6: FU_MEM_5
A7: FU_MEM_6
A8: FU_MEM_7
A9: FU_MEM_8
A10: FU_MEM_9
A11: FU_MEM_10
A12: FU_MEM_11
A13: FU_MEM_12
... A80: FU_MEM_79

Sheet Income
A1: a | B1: Back to Index | S1: Mandatory | AA1: =IF(ISBLANK(C297),1,C297)
A2: 1
A3: 0 | B3: Number of activities | C3: 1 | D3: =IF(ISBLANK(C3),"REQUIRED!","") | P3: =IF(ISBLANK(C3),1,0)
A4: 1 | B4: =_ref1 | E4: =_YA1 | F4: =_YA1 | G4: =_YA1 | H4: =_YA1 -> Y/A 2025 | I4: =_YA1 -> Y/A 2025 | J4: =_YA1 -> Y/A 2025 | K4: =_YA1 -> Y/A 2025 | L4: =_YA1 -> Y/A 2025 | ... N4: =_YA1 -> Y/A 2025 | U4: =B_Sheet!D4 | V4: =B_Sheet!E4
A5: 1 | B5: ="INCOME STATEMENT FOR THE YEAR ENDED "&B_Sheet!C4&" "&B_Sheet!D4&" "&B_Sheet!E4 | T5: =SUM(U5:V5) | U5: =IF(V4>2002,0,IF(U4="December",1,0)) | V5: =IF(V4=2002,1,IF(V4>2002,2,0))
A6: 1 | B6: NAME OF THE OPERATING ESTABLISHMENT | C6: 4500 | D6: =IF(O6<>C3,"Descriptions!","") | O6: =IF(tr=1,C3,COUNTA(E6:N6)) | Y6: 1 | Z6: =IF(A6=1,SUM($A6:$A$6),0)
A7: 1 | P7: =IF(O6<>C3,1,0) | Y7: 1 | Z7: =IF(A7=1,SUM($A$6:$A7),0)
A8: 1 | B8: OPERATION DESCRIPTION | C8: 4501 | D8: =IF(O8<>C3,"Descriptions!","") | O8: =IF(tr=1,C3,COUNTA(E8:N8)) | Y8: 1 | Z8: =IF(A8=1,SUM($A$6:$A8),0)
A9: 1 | P9: =IF(O8<>C3,1,0) | Y9: 1 | Z9: =IF(A9=1,SUM($A$6:$A9),0)
A10: 1 | B10: ACTIVITY NUMBER | C10: 4502 | E10: =IF($C$3="","",1) | F10: =IF($C$3=1,"",IF(E10="","",IF(E10+1>$C$3,"",E10+1))) | G10: =IF($C$3=1,"",IF(F10="","",IF(F10+1>$C$3,"",F10+1))) | H10: =IF($C$3=1,"",IF(G10="","",IF(G10+1>$C$3,"",G10+1))) | I10: =IF($C$3=1,"",IF(H10="","",IF(H10+1>$C$3,"",H10+1))) | J10: =IF($C$3=1,"",IF(I10="","",IF(I10+1>$C$3,"",I10+1))) | K10: =IF($C$3=1,"",IF(J10="","",IF(J10+1>$C$3,"",J10+1))) | L10: =IF($C$3=1,"",IF(K10="","",IF(K10+1>$C$3,"",K10+1))) | M10: =IF($C$3=1,"",IF(L10="","",IF(L10+1>$C$3,"",L10+1))) | N10: =IF($C$3=1,"",IF(M10="","",IF(M10+1>$C$3,"",M10+1))) | Y10: 1 | Z10: =IF(A10=1,SUM($A$6:$A10),0)
A11: 0 | B11: Item Description | C11: Code | E11: Dr ( + ) or Cr ( - ) | F11: Dr ( + ) or Cr ( - ) | G11: Dr ( + ) or Cr ( - ) | H11: Dr ( + ) or Cr ( - ) | I11: Dr ( + ) or Cr ( - ) | K11: Dr ( + ) or Cr ( - ) | L11: Dr ( + ) or Cr ( - ) | M11: Dr ( + ) or Cr ( - ) | N11: Dr ( + ) or Cr ( - ) | Z11: =IF(A11=1,SUM($A$6:$A11),0)
A12: =IF(OR(E12<>"",F12<>"",G12<>"",H12<>"",I12<>""),1,0) | B12: Sale of goods and rendering of services | C12: 5000 | Z12: =IF(A12=1,SUM($A$6:$A12),0) | AA12: =INDEX(activity,AB12,$AA$1) | AB12: 1
A13: =IF(OR(E13<>"",F13<>"",G13<>"",H13<>"",I13<>""),1,0) | B13: Export Sales | C13: 5001 | Z13: =IF(A13=1,SUM($A$6:$A13),0) | AA13: =INDEX(activity,AB13,$AA$1) | AB13: 2
A14: =IF(OR(E14<>"",F14<>"",G14<>"",H14<>"",I14<>""),1,0) -> 0 | B14: Wholesale Sales | C14: 5002 | Z14: =IF(A14=1,SUM($A$6:$A14),0) | AA14: =INDEX(activity,AB14,$AA$1) -> 0 | AB14: 3
A15: =IF(OR(E15<>"",F15<>"",G15<>"",H15<>"",I15<>""),1,0) -> 0 | B15: Retail Sales | C15: 5003 | Z15: =IF(A15=1,SUM($A$6:$A15),0) | AA15: =INDEX(activity,AB15,$AA$1) -> 0 | AB15: 4
A16: =IF(OR(E16<>"",F16<>"",G16<>"",H16<>"",I16<>""),1,0) -> 0 | B16: Sale of goods to related parties | C16: 5004 | Z16: =IF(A16=1,SUM($A$6:$A16),0) | AA16: =INDEX(activity,AB16,$AA$1) -> 0 | AB16: 5
A17: =IF(OR(E17<>"",F17<>"",G17<>"",H17<>"",I17<>""),1,0) -> 0 | B17: Interdivisional sales | C17: 5005 | Z17: =IF(A17=1,SUM($A$6:$A17),0) | AA17: =INDEX(activity,AB17,$AA$1) -> 0 | AB17: 6
A18: =IF(OR(E18<>"",F18<>"",G18<>"",H18<>"",I18<>""),1,0) -> 0 | B18: Income from production and / or processing - local | C18: 5006 | Z18: =IF(A18=1,SUM($A$6:$A18),0) | AA18: =INDEX(activity,AB18,$AA$1) -> 0 | AB18: 7
A19: =IF(OR(E19<>"",F19<>"",G19<>"",H19<>"",I19<>""),1,0) -> 0 | B19: Income from production and / or processing - foreign | C19: 5007 | Z19: =IF(A19=1,SUM($A$6:$A19),0) | AA19: =INDEX(activity,AB19,$AA$1) -> 0 | AB19: 8
A20: =IF(OR(E20<>"",F20<>"",G20<>"",H20<>"",I20<>""),1,0) -> 0 | B20: Income from production and / or processing - related parties | C20: 5008 | Z20: =IF(A20=1,SUM($A$6:$A20),0) | AA20: =INDEX(activity,AB20,$AA$1) -> 0 | AB20: 9
A21: =IF(OR(E21<>"",F21<>"",G21<>"",H21<>"",I21<>""),1,0) -> 0 | B21: Income from the rendering of services - local | C21: 5009 | Z21: =IF(A21=1,SUM($A$6:$A21),0) | AA21: =INDEX(activity,AB21,$AA$1) -> 0 | AB21: 10
A22: =IF(OR(E22<>"",F22<>"",G22<>"",H22<>"",I22<>""),1,0) -> 0 | B22: Income from the rendering of services - overseas | C22: 5010 | Z22: =IF(A22=1,SUM($A$6:$A22),0) | AA22: =INDEX(activity,AB22,$AA$1) -> 0 | AB22: 11
A23: =IF(OR(E23<>"",F23<>"",G23<>"",H23<>"",I23<>""),1,0) -> 0 | B23: Income from the rendering of services to related parties | C23: 5011 | Z23: =IF(A23=1,SUM($A$6:$A23),0) | AA23: =INDEX(activity,AB23,$AA$1) -> 0 | AB23: 12
A24: =IF(OR(E24<>"",F24<>"",G24<>"",H24<>"",I24<>""),1,0) -> 1 | B24: Total sales of goods and services | C24: 5099 | E24: =SUM(E12:E23) | F24: =SUM(F12:F23) | G24: =SUM(G12:G23) -> 0 | H24: =SUM(H12:H23) -> 0 | I24: =SUM(I12:I23) -> 0 | J24: =SUM(J12:J23) -> 0 | K24: =SUM(K12:K23) -> 0 | L24: =SUM(L12:L23) -> 0 | ... N24: =SUM(N12:N23) -> 0 | Z24: =IF(A24=1,SUM($A$6:$A24),0) | AA24: =INDEX(activity,AB24,$AA$1) -> -681223 | AB24: 13 | CA24: 1
A25: =IF(OR(E25<>"",F25<>"",G25<>"",H25<>"",I25<>""),1,0) -> 0 | B25: Income from Investments | C25: 5100 | Z25: =IF(A25=1,SUM($A$6:$A25),0) | AA25: =INDEX(activity,AB25,$AA$1) -> 0 | AB25: 14 | BA25: =SUM(E25:N25)
A26: =IF(OR(E26<>"",F26<>"",G26<>"",H26<>"",I26<>""),1,0) -> 0 | B26: Interest from Maltese banks | C26: 5101 | Z26: =IF(A26=1,SUM($A$6:$A26),0) | AA26: =INDEX(activity,AB26,$AA$1) -> 0 | AB26: 15 | BA26: =SUM(E26:N26)
A27: =IF(OR(E27<>"",F27<>"",G27<>"",H27<>"",I27<>""),1,0) -> 0 | B27: Interest received or receivable from shareholders and / or directors | C27: 5102 | Z27: =IF(A27=1,SUM($A$6:$A27),0) | AA27: =INDEX(activity,AB27,$AA$1) -> 0 | AB27: 16 | BA27: =SUM(E27:N27) -> 0
A28: =IF(OR(E28<>"",F28<>"",G28<>"",H28<>"",I28<>""),1,0) -> 0 | B28: Interest received or receivable from related parties | C28: 5103 | Z28: =IF(A28=1,SUM($A$6:$A28),0) | AA28: =INDEX(activity,AB28,$AA$1) -> 0 | AB28: 17 | BA28: =SUM(E28:N28) -> 0
A29: =IF(OR(E29<>"",F29<>"",G29<>"",H29<>"",I29<>""),1,0) -> 0 | B29: Loan interest - from local sources | C29: 5104 | Z29: =IF(A29=1,SUM($A$6:$A29),0) | AA29: =INDEX(activity,AB29,$AA$1) -> 0 | AB29: 18 | BA29: =SUM(E29:N29) -> 0
A30: =IF(OR(E30<>"",F30<>"",G30<>"",H30<>"",I30<>""),1,0) -> 0 | B30: Securities interest - from local sources | C30: 5105 | Z30: =IF(A30=1,SUM($A$6:$A30),0) | AA30: =INDEX(activity,AB30,$AA$1) -> 0 | AB30: 19 | BA30: =SUM(E30:N30) -> 0
A31: =IF(OR(E31<>"",F31<>"",G31<>"",H31<>"",I31<>""),1,0) -> 0 | B31: Interest from other Maltese sources | C31: 5106 | Z31: =IF(A31=1,SUM($A$6:$A31),0) | AA31: =INDEX(activity,AB31,$AA$1) -> 0 | AB31: 20 | BA31: =SUM(E31:N31) -> 0
A32: =IF(OR(E32<>"",F32<>"",G32<>"",H32<>"",I32<>""),1,0) -> 0 | B32: Interest from foreign banks | C32: 5107 | Z32: =IF(A32=1,SUM($A$6:$A32),0) | AA32: =INDEX(activity,AB32,$AA$1) -> 0 | AB32: 21 | BA32: =SUM(E32:N32) -> 0 | BD32: =BA32
A33: =IF(OR(E33<>"",F33<>"",G33<>"",H33<>"",I33<>""),1,0) -> 0 | B33: Loan interest - from foreign sources | C33: 5108 | Z33: =IF(A33=1,SUM($A$6:$A33),0) | AA33: =INDEX(activity,AB33,$AA$1) -> 0 | AB33: 22 | BA33: =SUM(E33:N33) -> 0 | BD33: =BA33
A34: =IF(OR(E34<>"",F34<>"",G34<>"",H34<>"",I34<>""),1,0) -> 0 | B34: Securities interest - from foreign sources | C34: 5109 | Z34: =IF(A34=1,SUM($A$6:$A34),0) | AA34: =INDEX(activity,AB34,$AA$1) -> 0 | AB34: 23 | BA34: =SUM(E34:N34) -> 0 | BD34: =BA34
A35: =IF(OR(E35<>"",F35<>"",G35<>"",H35<>"",I35<>""),1,0) -> 0 | B35: Interest from other foreign sources | C35: 5110 | Z35: =IF(A35=1,SUM($A$6:$A35),0) | AA35: =INDEX(activity,AB35,$AA$1) -> 0 | AB35: 24 | BA35: =SUM(E35:N35) -> 0 | BB35: =SUM(BA25:BA35) | BD35: =BA35
A36: =IF(OR(E36<>"",F36<>"",G36<>"",H36<>"",I36<>""),1,0) -> 0 | B36: Dividends from Maltese sources | C36: 5111 | Z36: =IF(A36=1,SUM($A$6:$A36),0) | AA36: =INDEX(activity,AB36,$AA$1) -> 0 | AB36: 25 | BA36: =SUM(E36:N36) -> 0 | BD36: =BA59 | BE36: =SUM(BD32:BD36)
A37: =IF(OR(E37<>"",F37<>"",G37<>"",H37<>"",I37<>""),1,0) -> 0 | B37: Dividends from foreign sources | C37: 5112 | Z37: =IF(A37=1,SUM($A$6:$A37),0) | AA37: =INDEX(activity,AB37,$AA$1) -> 0 | AB37: 26 | BA37: =SUM(E37:N37) -> 0 | BB37: =BA37+BA36
A38: =IF(OR(E38<>"",F38<>"",G38<>"",H38<>"",I38<>""),1,0) -> 0 | B38: Commission Income | C38: 5190 | Z38: =IF(A38=1,SUM($A$6:$A38),0) | AA38: =INDEX(activity,AB38,$AA$1) -> 0 | AB38: 27
A39: =IF(OR(E39<>"",F39<>"",G39<>"",H39<>"",I39<>""),1,0) -> 0 | B39: Commission income on real estate transactions | C39: 5191 | Z39: =IF(A39=1,SUM($A$6:$A39),0) | AA39: =INDEX(activity,AB39,$AA$1) -> 0 | AB39: 28
A40: =IF(OR(E40<>"",F40<>"",G40<>"",H40<>"",I40<>""),1,0) -> 0 | B40: Rental income | C40: 5200 | Z40: =IF(A40=1,SUM($A$6:$A40),0) | AA40: =INDEX(activity,AB40,$AA$1) -> 0 | AB40: 29 | BA40: =SUM(E40:N40)
...

Sheet Income_Summary
L1: =IF(OR(D6<> 0,D8<>0),0,1) | M1: =IF(OR(E6<> 0,E8<>0),0,1) | N1: =IF(OR(F6<> 0,F8<>0),0,1) | O1: =IF(OR(G6<> 0,G8<>0),0,1) | P1: =IF(OR(H6<> 0,H8<>0),0,1)
B4: =Income!B5
B5: Item Description | C5: Code
B6: =IF(ROW() -5<= MAX(Income!$Z$6:$Z$289),INDEX(Income!$B$6:$Z$289,MATCH(ROW()-5,Income!$Z$6:$Z$289,0),1),"") | C6: =IF(ROW() -5<= MAX(Income!$Z$6:$Z$289),INDEX(Income!$B$6:$Z$289,MATCH(ROW()-5,Income!$Z$6:$Z$289,0),2),"") | D6: =IF(ROW() -5<= MAX(Income!$Z$6:$Z$289),INDEX(Income!$B$6:$Z$289,MATCH(ROW()-5,Income!$Z$6:$Z$289,0),4),"") | E6: =IF(ROW() -5<= MAX(Income!$Z$6:$Z$289),INDEX(Income!$C$6:$Z$289,MATCH(ROW()-5,Income!$Z$6:$Z$289,0),4),"") | F6: =IF(ROW() -5<= MAX(Income!$Z$6:$Z$289),INDEX(Income!$D$6:$Z$289,MATCH(ROW()-5,Income!$Z$6:$Z$289,0),4),"") | G6: =IF(ROW() -5<= MAX(Income!$Z$6:$Z$289),INDEX(Income!$E$6:$Z$289,MATCH(ROW()-5,Income!$Z$6:$Z$289,0),4),"") | H6: =IF(ROW() -5<= MAX(Income!$Z$6:$Z$289),INDEX(Income!$F$6:$Z$289,MATCH(ROW()-5,Income!$Z$6:$Z$289,0),4),"") | K6: =IF(ROW() -5<= MAX(Income!$Z$6:$Z$289),INDEX(Income!$B$6:$Z$289,MATCH(ROW()-5,Income!$Z$6:$Z$289,0),24),"")
K7: =IF(ROW() -5<= MAX(Income!$Z$6:$Z$289),INDEX(Income!$B$6:$Z$289,MATCH(ROW()-5,Income!$Z$6:$Z$289,0),24),"")
B8: =IF(ROW() -5<= MAX(Income!$Z$6:$Z$289),INDEX(Income!$B$6:$Z$289,MATCH(ROW()-5,Income!$Z$6:$Z$289,0),1),"") | C8: =IF(ROW() -5<= MAX(Income!$Z$6:$Z$289),INDEX(Income!$B$6:$Z$289,MATCH(ROW()-5,Income!$Z$6:$Z$289,0),2),"") | D8: =IF(ROW() -5<= MAX(Income!$Z$6:$Z$289),INDEX(Income!$B$6:$Z$289,MATCH(ROW()-5,Income!$Z$6:$Z$289,0),4),"") | E8: =IF(ROW() -5<= MAX(Income!$Z$6:$Z$289),INDEX(Income!$C$6:$Z$289,MATCH(ROW()-5,Income!$Z$6:$Z$289,0),4),"") | F8: =IF(ROW() -5<= MAX(Income!$Z$6:$Z$289),INDEX(Income!$D$6:$Z$289,MATCH(ROW()-5,Income!$Z$6:$Z$289,0),4),"") | G8: =IF(ROW() -5<= MAX(Income!$Z$6:$Z$289),INDEX(Income!$E$6:$Z$289,MATCH(ROW()-5,Income!$Z$6:$Z$289,0),4),"") | H8: =IF(ROW() -5<= MAX(Income!$Z$6:$Z$289),INDEX(Income!$F$6:$Z$289,MATCH(ROW()-5,Income!$Z$6:$Z$289,0),4),"") | K8: =IF(ROW() -5<= MAX(Income!$Z$6:$Z$289),INDEX(Income!$B$6:$Z$289,MATCH(ROW()-5,Income!$Z$6:$Z$289,0),24),"")
K9: =IF(ROW() -5<= MAX(Income!$Z$6:$Z$289),INDEX(Income!$B$6:$Z$289,MATCH(ROW()-5,Income!$Z$6:$Z$289,0),24),"")
B10: =IF(ROW() -5<= MAX(Income!$Z$6:$Z$289),INDEX(Income!$B$6:$Z$289,MATCH(ROW()-5,Income!$Z$6:$Z$289,0),1),"") | C10: =IF(ROW() -5<= MAX(Income!$Z$6:$Z$289),INDEX(Income!$B$6:$Z$289,MATCH(ROW()-5,Income!$Z$6:$Z$289,0),2),"") | D10: =IF(ROW() -5<= MAX(Income!$Z$6:$Z$289),INDEX(Income!$B$6:$Z$289,MATCH(ROW()-5,Income!$Z$6:$Z$289,0),4),"") | E10: =IF(ROW() -5<= MAX(Income!$Z$6:$Z$289),INDEX(Income!$C$6:$Z$289,MATCH(ROW()-5,Income!$Z$6:$Z$289,0),4),"") | F10: =IF(ROW() -5<= MAX(Income!$Z$6:$Z$289),INDEX(Income!$D$6:$Z$289,MATCH(ROW()-5,Income!$Z$6:$Z$289,0),4),"") | G10: =IF(ROW() -5<= MAX(Income!$Z$6:$Z$289),INDEX(Income!$E$6:$Z$289,MATCH(ROW()-5,Income!$Z$6:$Z$289,0),4),"") | H10: =IF(ROW() -5<= MAX(Income!$Z$6:$Z$289),INDEX(Income!$F$6:$Z$289,MATCH(ROW()-5,Income!$Z$6:$Z$289,0),4),"") | K10: =IF(ROW() -5<= MAX(Income!$Z$6:$Z$289),INDEX(Income!$B$6:$Z$289,MATCH(ROW()-5,Income!$Z$6:$Z$289,0),24),"")
B11: =IF(ROW() -5<= MAX(Income!$Z$6:$Z$289),INDEX(Income!$B$6:$Z$289,MATCH(ROW()-5,Income!$Z$6:$Z$289,0),1),"") | C11: =IF(ROW() -5<= MAX(Income!$Z$6:$Z$289),INDEX(Income!$B$6:$Z$289,MATCH(ROW()-5,Income!$Z$6:$Z$289,0),2),"") | D11: =IF(ROW() -5<= MAX(Income!$Z$6:$Z$289),INDEX(Income!$B$6:$Z$289,MATCH(ROW()-5,Income!$Z$6:$Z$289,0),4),"") | E11: =IF(ROW() -5<= MAX(Income!$Z$6:$Z$289),INDEX(Income!$C$6:$Z$289,MATCH(ROW()-5,Income!$Z$6:$Z$289,0),4),"") | F11: =IF(ROW() -5<= MAX(Income!$Z$6:$Z$289),INDEX(Income!$D$6:$Z$289,MATCH(ROW()-5,Income!$Z$6:$Z$289,0),4),"") | G11: =IF(ROW() -5<= MAX(Income!$Z$6:$Z$289),INDEX(Income!$E$6:$Z$289,MATCH(ROW()-5,Income!$Z$6:$Z$289,0),4),"") | H11: =IF(ROW() -5<= MAX(Income!$Z$6:$Z$289),INDEX(Income!$F$6:$Z$289,MATCH(ROW()-5,Income!$Z$6:$Z$289,0),4),"") | K11: =IF(ROW() -5<= MAX(Income!$Z$6:$Z$289),INDEX(Income!$B$6:$Z$289,MATCH(ROW()-5,Income!$Z$6:$Z$289,0),24),"")
B12: =IF(ROW() -5<= MAX(Income!$Z$6:$Z$289),INDEX(Income!$B$6:$Z$289,MATCH(ROW()-5,Income!$Z$6:$Z$289,0),1),"") | C12: =IF(ROW() -5<= MAX(Income!$Z$6:$Z$289),INDEX(Income!$B$6:$Z$289,MATCH(ROW()-5,Income!$Z$6:$Z$289,0),2),"") | D12: =IF(ROW() -5<= MAX(Income!$Z$6:$Z$289),INDEX(Income!$B$6:$Z$289,MATCH(ROW()-5,Income!$Z$6:$Z$289,0),4),"") | E12: =IF(ROW() -5<= MAX(Income!$Z$6:$Z$289),INDEX(Income!$C$6:$Z$289,MATCH(ROW()-5,Income!$Z$6:$Z$289,0),4),"") | F12: =IF(ROW() -5<= MAX(Income!$Z$6:$Z$289),INDEX(Income!$D$6:$Z$289,MATCH(ROW()-5,Income!$Z$6:$Z$289,0),4),"") | G12: =IF(ROW() -5<= MAX(Income!$Z$6:$Z$289),INDEX(Income!$E$6:$Z$289,MATCH(ROW()-5,Income!$Z$6:$Z$289,0),4),"") | H12: =IF(ROW() -5<= MAX(Income!$Z$6:$Z$289),INDEX(Income!$F$6:$Z$289,MATCH(ROW()-5,Income!$Z$6:$Z$289,0),4),"") | K12: =IF(ROW() -5<= MAX(Income!$Z$6:$Z$289),INDEX(Income!$B$6:$Z$289,MATCH(ROW()-5,Income!$Z$6:$Z$289,0),24),"")
B13: =IF(ROW() -5<= MAX(Income!$Z$6:$Z$289),INDEX(Income!$B$6:$Z$289,MATCH(ROW()-5,Income!$Z$6:$Z$289,0),1),"") | C13: =IF(ROW() -5<= MAX(Income!$Z$6:$Z$289),INDEX(Income!$B$6:$Z$289,MATCH(ROW()-5,Income!$Z$6:$Z$289,0),2),"") | D13: =IF(ROW() -5<= MAX(Income!$Z$6:$Z$289),INDEX(Income!$B$6:$Z$289,MATCH(ROW()-5,Income!$Z$6:$Z$289,0),4),"") | E13: =IF(ROW() -5<= MAX(Income!$Z$6:$Z$289),INDEX(Income!$C$6:$Z$289,MATCH(ROW()-5,Income!$Z$6:$Z$289,0),4),"") | F13: =IF(ROW() -5<= MAX(Income!$Z$6:$Z$289),INDEX(Income!$D$6:$Z$289,MATCH(ROW()-5,Income!$Z$6:$Z$289,0),4),"") | G13: =IF(ROW() -5<= MAX(Income!$Z$6:$Z$289),INDEX(Income!$E$6:$Z$289,MATCH(ROW()-5,Income!$Z$6:$Z$289,0),4),"") | H13: =IF(ROW() -5<= MAX(Income!$Z$6:$Z$289),INDEX(Income!$F$6:$Z$289,MATCH(ROW()-5,Income!$Z$6:$Z$289,0),4),"") | K13: =IF(ROW() -5<= MAX(Income!$Z$6:$Z$289),INDEX(Income!$B$6:$Z$289,MATCH(ROW()-5,Income!$Z$6:$Z$289,0),24),"")
B14: =IF(ROW() -5<= MAX(Income!$Z$6:$Z$289),INDEX(Income!$B$6:$Z$289,MATCH(ROW()-5,Income!$Z$6:$Z$289,0),1),"") | C14: =IF(ROW() -5<= MAX(Income!$Z$6:$Z$289),INDEX(Income!$B$6:$Z$289,MATCH(ROW()-5,Income!$Z$6:$Z$289,0),2),"") | D14: =IF(ROW() -5<= MAX(Income!$Z$6:$Z$289),INDEX(Income!$B$6:$Z$289,MATCH(ROW()-5,Income!$Z$6:$Z$289,0),4),"") | E14: =IF(ROW() -5<= MAX(Income!$Z$6:$Z$289),INDEX(Income!$C$6:$Z$289,MATCH(ROW()-5,Income!$Z$6:$Z$289,0),4),"") | F14: =IF(ROW() -5<= MAX(Income!$Z$6:$Z$289),INDEX(Income!$D$6:$Z$289,MATCH(ROW()-5,Income!$Z$6:$Z$289,0),4),"") | G14: =IF(ROW() -5<= MAX(Income!$Z$6:$Z$289),INDEX(Income!$E$6:$Z$289,MATCH(ROW()-5,Income!$Z$6:$Z$289,0),4),"") | H14: =IF(ROW() -5<= MAX(Income!$Z$6:$Z$289),INDEX(Income!$F$6:$Z$289,MATCH(ROW()-5,Income!$Z$6:$Z$289,0),4),"") | K14: =IF(ROW() -5<= MAX(Income!$Z$6:$Z$289),INDEX(Income!$B$6:$Z$289,MATCH(ROW()-5,Income!$Z$6:$Z$289,0),24),"")
B15: =IF(ROW() -5<= MAX(Income!$Z$6:$Z$289),INDEX(Income!$B$6:$Z$289,MATCH(ROW()-5,Income!$Z$6:$Z$289,0),1),"") | C15: =IF(ROW() -5<= MAX(Income!$Z$6:$Z$289),INDEX(Income!$B$6:$Z$289,MATCH(ROW()-5,Income!$Z$6:$Z$289,0),2),"") | D15: =IF(ROW() -5<= MAX(Income!$Z$6:$Z$289),INDEX(Income!$B$6:$Z$289,MATCH(ROW()-5,Income!$Z$6:$Z$289,0),4),"") | E15: =IF(ROW() -5<= MAX(Income!$Z$6:$Z$289),INDEX(Income!$C$6:$Z$289,MATCH(ROW()-5,Income!$Z$6:$Z$289,0),4),"") | F15: =IF(ROW() -5<= MAX(Income!$Z$6:$Z$289),INDEX(Income!$D$6:$Z$289,MATCH(ROW()-5,Income!$Z$6:$Z$289,0),4),"") | G15: =IF(ROW() -5<= MAX(Income!$Z$6:$Z$289),INDEX(Income!$E$6:$Z$289,MATCH(ROW()-5,Income!$Z$6:$Z$289,0),4),"") | H15: =IF(ROW() -5<= MAX(Income!$Z$6:$Z$289),INDEX(Income!$F$6:$Z$289,MATCH(ROW()-5,Income!$Z$6:$Z$289,0),4),"") | K15: =IF(ROW() -5<= MAX(Income!$Z$6:$Z$289),INDEX(Income!$B$6:$Z$289,MATCH(ROW()-5,Income!$Z$6:$Z$289,0),24),"")
B16: =IF(ROW() -5<= MAX(Income!$Z$6:$Z$289),INDEX(Income!$B$6:$Z$289,MATCH(ROW()-5,Income!$Z$6:$Z$289,0),1),"") | C16: =IF(ROW() -5<= MAX(Income!$Z$6:$Z$289),INDEX(Income!$B$6:$Z$289,MATCH(ROW()-5,Income!$Z$6:$Z$289,0),2),"") | D16: =IF(ROW() -5<= MAX(Income!$Z$6:$Z$289),INDEX(Income!$B$6:$Z$289,MATCH(ROW()-5,Income!$Z$6:$Z$289,0),4),"") | E16: =IF(ROW() -5<= MAX(Income!$Z$6:$Z$289),INDEX(Income!$C$6:$Z$289,MATCH(ROW()-5,Income!$Z$6:$Z$289,0),4),"") | F16: =IF(ROW() -5<= MAX(Income!$Z$6:$Z$289),INDEX(Income!$D$6:$Z$289,MATCH(ROW()-5,Income!$Z$6:$Z$289,0),4),"") | G16: =IF(ROW() -5<= MAX(Income!$Z$6:$Z$289),INDEX(Income!$E$6:$Z$289,MATCH(ROW()-5,Income!$Z$6:$Z$289,0),4),"") | H16: =IF(ROW() -5<= MAX(Income!$Z$6:$Z$289),INDEX(Income!$F$6:$Z$289,MATCH(ROW()-5,Income!$Z$6:$Z$289,0),4),"") | K16: =IF(ROW() -5<= MAX(Income!$Z$6:$Z$289),INDEX(Income!$B$6:$Z$289,MATCH(ROW()-5,Income!$Z$6:$Z$289,0),24),"")
B17: =IF(ROW() -5<= MAX(Income!$Z$6:$Z$289),INDEX(Income!$B$6:$Z$289,MATCH(ROW()-5,Income!$Z$6:$Z$289,0),1),"") | C17: =IF(ROW() -5<= MAX(Income!$Z$6:$Z$289),INDEX(Income!$B$6:$Z$289,MATCH(ROW()-5,Income!$Z$6:$Z$289,0),2),"") | D17: =IF(ROW() -5<= MAX(Income!$Z$6:$Z$289),INDEX(Income!$B$6:$Z$289,MATCH(ROW()-5,Income!$Z$6:$Z$289,0),4),"") | E17: =IF(ROW() -5<= MAX(Income!$Z$6:$Z$289),INDEX(Income!$C$6:$Z$289,MATCH(ROW()-5,Income!$Z$6:$Z$289,0),4),"") | F17: =IF(ROW() -5<= MAX(Income!$Z$6:$Z$289),INDEX(Income!$D$6:$Z$289,MATCH(ROW()-5,Income!$Z$6:$Z$289,0),4),"") | G17: =IF(ROW() -5<= MAX(Income!$Z$6:$Z$289),INDEX(Income!$E$6:$Z$289,MATCH(ROW()-5,Income!$Z$6:$Z$289,0),4),"") | H17: =IF(ROW() -5<= MAX(Income!$Z$6:$Z$289),INDEX(Income!$F$6:$Z$289,MATCH(ROW()-5,Income!$Z$6:$Z$289,0),4),"") | K17: =IF(ROW() -5<= MAX(Income!$Z$6:$Z$289),INDEX(Income!$B$6:$Z$289,MATCH(ROW()-5,Income!$Z$6:$Z$289,0),24),"")
B18: =IF(ROW() -5<= MAX(Income!$Z$6:$Z$289),INDEX(Income!$B$6:$Z$289,MATCH(ROW()-5,Income!$Z$6:$Z$289,0),1),"") | C18: =IF(ROW() -5<= MAX(Income!$Z$6:$Z$289),INDEX(Income!$B$6:$Z$289,MATCH(ROW()-5,Income!$Z$6:$Z$289,0),2),"") | D18: =IF(ROW() -5<= MAX(Income!$Z$6:$Z$289),INDEX(Income!$B$6:$Z$289,MATCH(ROW()-5,Income!$Z$6:$Z$289,0),4),"") | E18: =IF(ROW() -5<= MAX(Income!$Z$6:$Z$289),INDEX(Income!$C$6:$Z$289,MATCH(ROW()-5,Income!$Z$6:$Z$289,0),4),"") | F18: =IF(ROW() -5<= MAX(Income!$Z$6:$Z$289),INDEX(Income!$D$6:$Z$289,MATCH(ROW()-5,Income!$Z$6:$Z$289,0),4),"") | G18: =IF(ROW() -5<= MAX(Income!$Z$6:$Z$289),INDEX(Income!$E$6:$Z$289,MATCH(ROW()-5,Income!$Z$6:$Z$289,0),4),"") | H18: =IF(ROW() -5<= MAX(Income!$Z$6:$Z$289),INDEX(Income!$F$6:$Z$289,MATCH(ROW()-5,Income!$Z$6:$Z$289,0),4),"") | K18: =IF(ROW() -5<= MAX(Income!$Z$6:$Z$289),INDEX(Income!$B$6:$Z$289,MATCH(ROW()-5,Income!$Z$6:$Z$289,0),24),"")
B19: =IF(ROW() -5<= MAX(Income!$Z$6:$Z$289),INDEX(Income!$B$6:$Z$289,MATCH(ROW()-5,Income!$Z$6:$Z$289,0),1),"") | C19: =IF(ROW() -5<= MAX(Income!$Z$6:$Z$289),INDEX(Income!$B$6:$Z$289,MATCH(ROW()-5,Income!$Z$6:$Z$289,0),2),"") | D19: =IF(ROW() -5<= MAX(Income!$Z$6:$Z$289),INDEX(Income!$B$6:$Z$289,MATCH(ROW()-5,Income!$Z$6:$Z$289,0),4),"") | E19: =IF(ROW() -5<= MAX(Income!$Z$6:$Z$289),INDEX(Income!$C$6:$Z$289,MATCH(ROW()-5,Income!$Z$6:$Z$289,0),4),"") | F19: =IF(ROW() -5<= MAX(Income!$Z$6:$Z$289),INDEX(Income!$D$6:$Z$289,MATCH(ROW()-5,Income!$Z$6:$Z$289,0),4),"") | G19: =IF(ROW() -5<= MAX(Income!$Z$6:$Z$289),INDEX(Income!$E$6:$Z$289,MATCH(ROW()-5,Income!$Z$6:$Z$289,0),4),"") | H19: =IF(ROW() -5<= MAX(Income!$Z$6:$Z$289),INDEX(Income!$F$6:$Z$289,MATCH(ROW()-5,Income!$Z$6:$Z$289,0),4),"") | K19: =IF(ROW() -5<= MAX(Income!$Z$6:$Z$289),INDEX(Income!$B$6:$Z$289,MATCH(ROW()-5,Income!$Z$6:$Z$289,0),24),"")
B20: =IF(ROW() -5<= MAX(Income!$Z$6:$Z$289),INDEX(Income!$B$6:$Z$289,MATCH(ROW()-5,Income!$Z$6:$Z$289,0),1),"") | C20: =IF(ROW() -5<= MAX(Income!$Z$6:$Z$289),INDEX(Income!$B$6:$Z$289,MATCH(ROW()-5,Income!$Z$6:$Z$289,0),2),"") | D20: =IF(ROW() -5<= MAX(Income!$Z$6:$Z$289),INDEX(Income!$B$6:$Z$289,MATCH(ROW()-5,Income!$Z$6:$Z$289,0),4),"") | E20: =IF(ROW() -5<= MAX(Income!$Z$6:$Z$289),INDEX(Income!$C$6:$Z$289,MATCH(ROW()-5,Income!$Z$6:$Z$289,0),4),"") | F20: =IF(ROW() -5<= MAX(Income!$Z$6:$Z$289),INDEX(Income!$D$6:$Z$289,MATCH(ROW()-5,Income!$Z$6:$Z$289,0),4),"") | G20: =IF(ROW() -5<= MAX(Income!$Z$6:$Z$289),INDEX(Income!$E$6:$Z$289,MATCH(ROW()-5,Income!$Z$6:$Z$289,0),4),"") | H20: =IF(ROW() -5<= MAX(Income!$Z$6:$Z$289),INDEX(Income!$F$6:$Z$289,MATCH(ROW()-5,Income!$Z$6:$Z$289,0),4),"") | K20: =IF(ROW() -5<= MAX(Income!$Z$6:$Z$289),INDEX(Income!$B$6:$Z$289,MATCH(ROW()-5,Income!$Z$6:$Z$289,0),24),"")
B21: =IF(ROW() -5<= MAX(Income!$Z$6:$Z$289),INDEX(Income!$B$6:$Z$289,MATCH(ROW()-5,Income!$Z$6:$Z$289,0),1),"") | C21: =IF(ROW() -5<= MAX(Income!$Z$6:$Z$289),INDEX(Income!$B$6:$Z$289,MATCH(ROW()-5,Income!$Z$6:$Z$289,0),2),"") | D21: =IF(ROW() -5<= MAX(Income!$Z$6:$Z$289),INDEX(Income!$B$6:$Z$289,MATCH(ROW()-5,Income!$Z$6:$Z$289,0),4),"") | E21: =IF(ROW() -5<= MAX(Income!$Z$6:$Z$289),INDEX(Income!$C$6:$Z$289,MATCH(ROW()-5,Income!$Z$6:$Z$289,0),4),"") | F21: =IF(ROW() -5<= MAX(Income!$Z$6:$Z$289),INDEX(Income!$D$6:$Z$289,MATCH(ROW()-5,Income!$Z$6:$Z$289,0),4),"") | G21: =IF(ROW() -5<= MAX(Income!$Z$6:$Z$289),INDEX(Income!$E$6:$Z$289,MATCH(ROW()-5,Income!$Z$6:$Z$289,0),4),"") | H21: =IF(ROW() -5<= MAX(Income!$Z$6:$Z$289),INDEX(Income!$F$6:$Z$289,MATCH(ROW()-5,Income!$Z$6:$Z$289,0),4),"") | K21: =IF(ROW() -5<= MAX(Income!$Z$6:$Z$289),INDEX(Income!$B$6:$Z$289,MATCH(ROW()-5,Income!$Z$6:$Z$289,0),24),"")
... B288: =IF(ROW() -5<= MAX(Income!$Z$6:$Z$289),INDEX(Income!$B$6:$Z$289,MATCH(ROW()-5,Income!$Z$6:$Z$289,0),1),"") | C288: =IF(ROW() -5<= MAX(Income!$Z$6:$Z$289),INDEX(Income!$B$6:$Z$289,MATCH(ROW()-5,Income!$Z$6:$Z$289,0),2),"") | D288: =IF(ROW() -5<= MAX(Income!$Z$6:$Z$289),INDEX(Income!$B$6:$Z$289,MATCH(ROW()-5,Income!$Z$6:$Z$289,0),4),"") | E288: =IF(ROW() -5<= MAX(Income!$Z$6:$Z$289),INDEX(Income!$C$6:$Z$289,MATCH(ROW()-5,Income!$Z$6:$Z$289,0),4),"") | F288: =IF(ROW() -5<= MAX(Income!$Z$6:$Z$289),INDEX(Income!$D$6:$Z$289,MATCH(ROW()-5,Income!$Z$6:$Z$289,0),4),"") | G288: =IF(ROW() -5<= MAX(Income!$Z$6:$Z$289),INDEX(Income!$E$6:$Z$289,MATCH(ROW()-5,Income!$Z$6:$Z$289,0),4),"") | H288: =IF(ROW() -5<= MAX(Income!$Z$6:$Z$289),INDEX(Income!$F$6:$Z$289,MATCH(ROW()-5,Income!$Z$6:$Z$289,0),4),"") | K288: =IF(ROW() -5<= MAX(Income!$Z$6:$Z$289),INDEX(Income!$B$6:$Z$289,MATCH(ROW()-5,Income!$Z$6:$Z$289,0),24),"")

Sheet TRA1
B1: =_ref1 | G1: =_YA1
B2: ITA - Article 14(1)(h) - Scientific Research
B3: Has the scientific research been carried out in Malta? | G3: Yes | I3: =IF(H3="",0,1) | J3: =IF(G3=B65,1,0)
B4: Are you exercising the option to inflate the expenditure by 50%? | G4: No | I4: =IF(H4="",0,1) | J4: =IF(G4=B65,1,0) | K4: =SUM(J3:J4)
B5: Please indicate the turnover for the year | I5: =IF(H5="",0,1) | J5: =IF(ISBLANK(G5),0,1)
J6: =SUM(J3:J5) | K6: =COUNTA(B10:G20,B23:G37,F42,F51)
B7: ALL EXPENDITURE INCURRED ON OR AFTER 1 JANUARY 2005 MUST BE REFLECTED IN TRA 42
B8: Details of expenditure on scientific research | G8: Amount
B9: Capital expenditure [in respect of which no deductions are allowed under par. (f) and (j) of the I.T.Act]
H10: =IF(J10=0,"",IF(J10=2,"","All details!")) | I10: =IF(H10="",0,1) | J10: =COUNTA(B10,G10)
H11: =IF(J11=0,"",IF(J11=2,"","All details!")) | I11: =IF(H11="",0,1) -> 0 | J11: =COUNTA(B11,G11)
H12: =IF(J12=0,"",IF(J12=2,"","All details!")) | I12: =IF(H12="",0,1) -> 0 | J12: =COUNTA(B12,G12) -> 0
H13: =IF(J13=0,"",IF(J13=2,"","All details!")) | I13: =IF(H13="",0,1) -> 0 | J13: =COUNTA(B13,G13) -> 0
H14: =IF(J14=0,"",IF(J14=2,"","All details!")) | I14: =IF(H14="",0,1) -> 0 | J14: =COUNTA(B14,G14) -> 0
H15: =IF(J15=0,"",IF(J15=2,"","All details!")) | I15: =IF(H15="",0,1) -> 0 | J15: =COUNTA(B15,G15) -> 0
H16: =IF(J16=0,"",IF(J16=2,"","All details!")) | I16: =IF(H16="",0,1) -> 0 | J16: =COUNTA(B16,G16) -> 0
H17: =IF(J17=0,"",IF(J17=2,"","All details!")) | I17: =IF(H17="",0,1) -> 0 | J17: =COUNTA(B17,G17) -> 0
H18: =IF(J18=0,"",IF(J18=2,"","All details!")) | I18: =IF(H18="",0,1) -> 0 | J18: =COUNTA(B18,G18) -> 0
H19: =IF(J19=0,"",IF(J19=2,"","All details!")) | I19: =IF(H19="",0,1) -> 0 | J19: =COUNTA(B19,G19) -> 0
H20: =IF(J20=0,"",IF(J20=2,"","All details!")) | I20: =IF(H20="",0,1) -> 0 | J20: =COUNTA(B20,G20) -> 0
B21: Total scientific research expenditure of a capital nature | G21: =SUM(G10:G20)
B22: Other expenditure on scientific research
H23: =IF(J23=0,"",IF(J23=2,"","All details!")) | I23: =IF(H23="",0,1) -> 0 | J23: =COUNTA(B23,G23) -> 0
H24: =IF(J24=0,"",IF(J24=2,"","All details!")) | I24: =IF(H24="",0,1) -> 0 | J24: =COUNTA(B24,G24) -> 0
H25: =IF(J25=0,"",IF(J25=2,"","All details!")) | I25: =IF(H25="",0,1) -> 0 | J25: =COUNTA(B25,G25) -> 0
H26: =IF(J26=0,"",IF(J26=2,"","All details!")) | I26: =IF(H26="",0,1) -> 0 | J26: =COUNTA(B26,G26) -> 0
H27: =IF(J27=0,"",IF(J27=2,"","All details!")) | I27: =IF(H27="",0,1) -> 0 | J27: =COUNTA(B27,G27) -> 0
H28: =IF(J28=0,"",IF(J28=2,"","All details!")) | I28: =IF(H28="",0,1) -> 0 | J28: =COUNTA(B28,G28) -> 0
H29: =IF(J29=0,"",IF(J29=2,"","All details!")) | I29: =IF(H29="",0,1) -> 0 | J29: =COUNTA(B29,G29) -> 0
H30: =IF(J30=0,"",IF(J30=2,"","All details!")) | I30: =IF(H30="",0,1) -> 0 | J30: =COUNTA(B30,G30) -> 0
H31: =IF(J31=0,"",IF(J31=2,"","All details!")) | I31: =IF(H31="",0,1) -> 0 | J31: =COUNTA(B31,G31) -> 0
H32: =IF(J32=0,"",IF(J32=2,"","All details!")) | I32: =IF(H32="",0,1) -> 0 | J32: =COUNTA(B32,G32) -> 0
H33: =IF(J33=0,"",IF(J33=2,"","All details!")) | I33: =IF(H33="",0,1) -> 0 | J33: =COUNTA(B33,G33) -> 0
H34: =IF(J34=0,"",IF(J34=2,"","All details!")) | I34: =IF(H34="",0,1) -> 0 | J34: =COUNTA(B34,G34) -> 0
... H37: =IF(J37=0,"",IF(J37=2,"","All details!")) | I37: =IF(H37="",0,1) -> 0 | J37: =COUNTA(B37,G37)
B38: Total other scientific research expenditure | G38: =SUM(G23:G37)
B39: Total expenditure on Scientific Research incurred during the year | G39: =ROUND(G21+G38,0)
B41: One sixth of the capital expenditure that can be claimed for the year | F41: =ROUND(G21/6,0)
B42: One sixth of the capital expenditure, incurred in prior years, claimed for the year
B43: Portion of capital expenditure on Scientific Research that can be claimed for the year | G43: =F41+F42
...

Sheet TRA2
A1: =_ref1 | J1: =_YA1
A2: BPA Regulation 13 - [Incentives for Job Creation]
A3: Documentation required
A4: a) Certificate issued by the Employment and Training Corporation [Regulation 13 (1)]
A5: b) Documentation referred to in Note 1 below
A6: c) Where applicable, the written approval by E.T.C., for training programmes provided by employers to qualifying individuals | AO6: Yes
A7: d) Where applicable, the written approval by ETC for claims of cash grant(s) in lieu of additional deductions. | AO7: No
